Traceback (most recent call last):
  File "/Users/raminasser/anaconda3/envs/software_project/lib/python3.9/site-packages/jupyter_cache/executors/utils.py", line 58, in single_nb_execution
    executenb(
  File "/Users/raminasser/anaconda3/envs/software_project/lib/python3.9/site-packages/nbclient/client.py", line 1319, in execute
    return NotebookClient(nb=nb, resources=resources, km=km, **kwargs).execute()
  File "/Users/raminasser/anaconda3/envs/software_project/lib/python3.9/site-packages/jupyter_core/utils/__init__.py", line 165, in wrapped
    return loop.run_until_complete(inner)
  File "/Users/raminasser/anaconda3/envs/software_project/lib/python3.9/asyncio/base_events.py", line 647, in run_until_complete
    return future.result()
  File "/Users/raminasser/anaconda3/envs/software_project/lib/python3.9/site-packages/nbclient/client.py", line 709, in async_execute
    await self.async_execute_cell(
  File "/Users/raminasser/anaconda3/envs/software_project/lib/python3.9/site-packages/nbclient/client.py", line 1062, in async_execute_cell
    await self._check_raise_for_error(cell, cell_index, exec_reply)
  File "/Users/raminasser/anaconda3/envs/software_project/lib/python3.9/site-packages/nbclient/client.py", line 918, in _check_raise_for_error
    raise CellExecutionError.from_cell_and_msg(cell, exec_reply_content)
nbclient.exceptions.CellExecutionError: An error occurred while executing the following cell:
------------------
print(MLB_team['Los Angeles'])  # KeyError
------------------


[0;31m---------------------------------------------------------------------------[0m
[0;31mKeyError[0m                                  Traceback (most recent call last)
Cell [0;32mIn[39], line 1[0m
[0;32m----> 1[0m [38;5;28mprint[39m([43mMLB_team[49m[43m[[49m[38;5;124;43m'[39;49m[38;5;124;43mLos Angeles[39;49m[38;5;124;43m'[39;49m[43m][49m)  [38;5;66;03m# KeyError[39;00m

[0;31mKeyError[0m: 'Los Angeles'

